Workbook

Sheet Índice
A4: PROYECCIONES DE POBLACIÓN Y ESTUDIOS DEMOGRÁFICOS (PPED)
A6: DIRECCIÓN TÉCNICA DE CENSOS Y DEMOGRAFÍA (DCD)
A9: 1. | B9: Introducción PPED
B10: Actualización de la serie nacional de población, 2018 a 2070
A11: 2 | B11: Desagregación por área, sexo y edades simples
B12: =PobNacionalxÁreaSexoEdad!A5 -> NACIONAL. PROYECCIONES DE POBLACIÓN POR ÁREA GEOGRÁFICA SEGÚN SEXO Y EDADES SIMPLES, PERIODO 2018-2070

Sheet PPED
A3: PROYECCIONES DE POBLACIÓN Y ESTUDIOS DEMOGRÁFICOS (PPED)
A5: Actualizado el 18 de Julio de 2025
A6: NACIONAL. PROYECCIONES DE POBLACIÓN POR ÁREA GEOGRÁFICA. PERIODO 2018-2070
A7: Se incorporan nuevas tendencias observadas en la dinámica poblacional asociada a la aceleración del cambio en los componentes demográficos y mejoras técnicas en la producción estadística de esta operación derivada de los censos nacionales de población y vivienda, así como de las estadísticas de los hechos vitales.
A9: NACIONAL. PROYECCIONES DE POBLACIÓN POR ÁREA GEOGRÁFICA SEGÚN SEXO Y EDADES SIMPLES. PERIODO 2018-2070
A10: Aplicación del modelo de componentes de cohortes con un enfoque adaptado multiregional.
A11: Dirección técnica de Censos y Demografía (DCD)

Sheet PobNacionalxÁreaSexoEdad
A3: PROYECCIONES DE POBLACIÓN Y ESTUDIOS DEMOGRÁFICOS (PPED)
A5: NACIONAL. PROYECCIONES DE POBLACIÓN POR ÁREA GEOGRÁFICA SEGÚN SEXO Y EDADES SIMPLES, PERIODO 2018-2070
A7: PROYECCIONES DE POBLACIÓN POR ÁREA, SEGÚN SEXO Y EDAD SIMPLE. AÑOS 2018 A 2070
A8: TERRITORIO | B8: AÑO | C8: ÁREA GEOGRÁFICA | D8: TOTAL | G8: HOMBRES | DD8: MUJERES | HA8: TOTAL (AMBOS SEXOS)
D9: Total | E9: Hombres | F9: Mujeres | G9: Hombres 0 años | H9: Hombres 1 año | I9: Hombres 2 años | J9: Hombres 3 años | K9: Hombres 4 años | L9: Hombres 5 años | M9: Hombres 6 años | N9: Hombres 7 años | O9: Hombres 8 años | P9: Hombres 9 años | Q9: Hombres 10 años | R9: Hombres 11 años | S9: Hombres 12 años | T9: Hombres 13 años | U9: Hombres 14 años | V9: Hombres 15 años | W9: Hombres 16 años | X9: Hombres 17 años | Y9: Hombres 18 años | Z9: Hombres 19 años | AA9: Hombres 20 años | AB9: Hombres 21 años | AC9: Hombres 22 años | AD9: Hombres 23 años | AE9: Hombres 24 años | AF9: Hombres 25 años | AG9: Hombres 26 años | AH9: Hombres 27 años | AI9: Hombres 28 años | AJ9: Hombres 29 años | AK9: Hombres 30 años | AL9: Hombres 31 años | AM9: Hombres 32 años | AN9: Hombres 33 años | AO9: Hombres 34 años | AP9: Hombres 35 años | AQ9: Hombres 36 años | AR9: Hombres 37 años | AS9: Hombres 38 años | AT9: Hombres 39 años | AU9: Hombres 40 años | AV9: Hombres 41 años | AW9: Hombres 42 años | AX9: Hombres 43 años | AY9: Hombres 44 años | AZ9: Hombres 45 años | BA9: Hombres 46 años | BB9: Hombres 47 años | BC9: Hombres 48 años | BD9: Hombres 49 años | BE9: Hombres 50 años | BF9: Hombres 51 años | BG9: Hombres 52 años | BH9: Hombres 53 años | BI9: Hombres 54 años | BJ9: Hombres 55 años | BK9: Hombres 56 años | BL9: Hombres 57 años | BM9: Hombres 58 años | BN9: Hombres 59 años | BO9: Hombres 60 años | BP9: Hombres 61 años | BQ9: Hombres 62 años | BR9: Hombres 63 años | BS9: Hombres 64 años | BT9: Hombres 65 años | BU9: Hombres 66 años | BV9: Hombres 67 años | BW9: Hombres 68 años | BX9: Hombres 69 años | BY9: Hombres 70 años | BZ9: Hombres 71 años | CA9: Hombres 72 años | CB9: Hombres 73 años | CC9: Hombres 74 años | CD9: Hombres 75 años | CE9: Hombres 76 años | CF9: Hombres 77 años | CG9: Hombres 78 años | CH9: Hombres 79 años | CI9: Hombres 80 años | CJ9: Hombres 81 años | CK9: Hombres 82 años | CL9: Hombres 83 años | CM9: Hombres 84 años | CN9: Hombres 85 años | CO9: Hombres 86 años | CP9: Hombres 87 años | CQ9: Hombres 88 años | CR9: Hombres 89 años | CS9: Hombres 90 años | CT9: Hombres 91 años | CU9: Hombres 92 años | CV9: Hombres 93 años | CW9: Hombres 94 años | CX9: Hombres 95 años | CY9: Hombres 96 años | CZ9: Hombres 97 años | DA9: Hombres 98 años | DB9: Hombres 99 años | DC9: Hombres 100 años y más | DD9: Mujeres 0 años | DE9: Mujeres 1 año | DF9: Mujeres 2 años | DG9: Mujeres 3 años | DH9: Mujeres 4 años | DI9: Mujeres 5 años | DJ9: Mujeres 6 años | DK9: Mujeres 7 años | DL9: Mujeres 8 años | DM9: Mujeres 9 años | DN9: Mujeres 10 años | DO9: Mujeres 11 años | DP9: Mujeres 12 años | DQ9: Mujeres 13 años | DR9: Mujeres 14 años | DS9: Mujeres 15 años | DT9: Mujeres 16 años | DU9: Mujeres 17 años | DV9: Mujeres 18 años | DW9: Mujeres 19 años | DX9: Mujeres 20 años | DY9: Mujeres 21 años | DZ9: Mujeres 22 años | EA9: Mujeres 23 años | EB9: Mujeres 24 años | EC9: Mujeres 25 años | ED9: Mujeres 26 años | EE9: Mujeres 27 años | EF9: Mujeres 28 años | EG9: Mujeres 29 años | EH9: Mujeres 30 años | EI9: Mujeres 31 años | EJ9: Mujeres 32 años | EK9: Mujeres 33 años | EL9: Mujeres 34 años | EM9: Mujeres 35 años | EN9: Mujeres 36 años | EO9: Mujeres 37 años | EP9: Mujeres 38 años | EQ9: Mujeres 39 años | ER9: Mujeres 40 años | ES9: Mujeres 41 años | ET9: Mujeres 42 años | EU9: Mujeres 43 años | EV9: Mujeres 44 años | EW9: Mujeres 45 años | EX9: Mujeres 46 años | EY9: Mujeres 47 años | EZ9: Mujeres 48 años | FA9: Mujeres 49 años | FB9: Mujeres 50 años | FC9: Mujeres 51 años | FD9: Mujeres 52 años | FE9: Mujeres 53 años | FF9: Mujeres 54 años | FG9: Mujeres 55 años | FH9: Mujeres 56 años | FI9: Mujeres 57 años | FJ9: Mujeres 58 años | FK9: Mujeres 59 años | FL9: Mujeres 60 años | FM9: Mujeres 61 años | FN9: Mujeres 62 años | FO9: Mujeres 63 años | FP9: Mujeres 64 años | FQ9: Mujeres 65 años | FR9: Mujeres 66 años | FS9: Mujeres 67 años | FT9: Mujeres 68 años | FU9: Mujeres 69 años | FV9: Mujeres 70 años | FW9: Mujeres 71 años | FX9: Mujeres 72 años | FY9: Mujeres 73 años | FZ9: Mujeres 74 años | GA9: Mujeres 75 años | GB9: Mujeres 76 años | GC9: Mujeres 77 años | GD9: Mujeres 78 años | GE9: Mujeres 79 años | GF9: Mujeres 80 años | GG9: Mujeres 81 años | GH9: Mujeres 82 años | GI9: Mujeres 83 años | GJ9: Mujeres 84 años | GK9: Mujeres 85 años | GL9: Mujeres 86 años | GM9: Mujeres 87 años | GN9: Mujeres 88 años | GO9: Mujeres 89 años | GP9: Mujeres 90 años | GQ9: Mujeres 91 años | GR9: Mujeres 92 años | GS9: Mujeres 93 años | GT9: Mujeres 94 años | GU9: Mujeres 95 años | GV9: Mujeres 96 años | GW9: Mujeres 97 años | GX9: Mujeres 98 años | GY9: Mujeres 99 años | GZ9: Mujeres 100 años y más | HA9: Total 0 años | HB9: Total 1 año | HC9: Total 2 años | HD9: Total 3 años | HE9: Total 4 años | HF9: Total 5 años | HG9: Total 6 años | HH9: Total 7 años | HI9: Total 8 años | HJ9: Total 9 años | HK9: Total 10 años | HL9: Total 11 años | HM9: Total 12 años | HN9: Total 13 años | HO9: Total 14 años | HP9: Total 15 años | HQ9: Total 16 años | HR9: Total 17 años | HS9: Total 18 años | HT9: Total 19 años | HU9: Total 20 años | HV9: Total 21 años | HW9: Total 22 años | HX9: Total 23 años | HY9: Total 24 años | HZ9: Total 25 años | IA9: Total 26 años | IB9: Total 27 años | IC9: Total 28 años | ID9: Total 29 años | IE9: Total 30 años | IF9: Total 31 años | IG9: Total 32 años | IH9: Total 33 años | II9: Total 34 años | IJ9: Total 35 años | IK9: Total 36 años | IL9: Total 37 años | IM9: Total 38 años | IN9: Total 39 años | IO9: Total 40 años | IP9: Total 41 años | IQ9: Total 42 años | IR9: Total 43 años | IS9: Total 44 años | IT9: Total 45 años | IU9: Total 46 años | IV9: Total 47 años | IW9: Total 48 años | IX9: Total 49 años | IY9: Total 50 años | IZ9: Total 51 años | JA9: Total 52 años | JB9: Total 53 años | JC9: Total 54 años | JD9: Total 55 años | JE9: Total 56 años | JF9: Total 57 años | JG9: Total 58 años | JH9: Total 59 años | JI9: Total 60 años | JJ9: Total 61 años | JK9: Total 62 años | JL9: Total 63 años | JM9: Total 64 años | JN9: Total 65 años | JO9: Total 66 años | JP9: Total 67 años | JQ9: Total 68 años | JR9: Total 69 años | JS9: Total 70 años | JT9: Total 71 años | JU9: Total 72 años | JV9: Total 73 años | JW9: Total 74 años | JX9: Total 75 años | JY9: Total 76 años | JZ9: Total 77 años | KA9: Total 78 años | KB9: Total 79 años | KC9: Total 80 años | KD9: Total 81 años | KE9: Total 82 años | KF9: Total 83 años | KG9: Total 84 años | KH9: Total 85 años | KI9: Total 86 años | KJ9: Total 87 años | KK9: Total 88 años | KL9: Total 89 años | KM9: Total 90 años | KN9: Total 91 años | KO9: Total 92 años | KP9: Total 93 años | KQ9: Total 94 años | KR9: Total 95 años | KS9: Total 96 años | KT9: Total 97 años | KU9: Total 98 años | KV9: Total 99 años | KW9: Total 100 años y más
A10: Total Nacional | B10: 2018 | C10: Cabecera | D10: 36414521 | E10: 17450356 | F10: 18964165 | G10: 267725 | H10: 271659 | I10: 275579 | J10: 279172 | K10: 282059 | L10: 284726 | M10: 288053 | N10: 291880 | O10: 295932 | P10: 299857 | Q10: 303787 | R10: 307960 | S10: 308600 | T10: 308921 | U10: 308508 | V10: 309013 | W10: 309651 | X10: 312341 | Y10: 311464 | Z10: 311626 | AA10: 312571 | AB10: 314681 | AC10: 316457 | AD10: 317727 | AE10: 316270 | AF10: 311156 | AG10: 304416 | AH10: 297294 | AI10: 289727 | AJ10: 282227 | AK10: 273730 | AL10: 267924 | AM10: 262868 | AN10: 259141 | AO10: 256726 | AP10: 253976 | AQ10: 250172 | AR10: 246544 | AS10: 240499 | AT10: 233169 | AU10: 224143 | AV10: 216740 | AW10: 208217 | AX10: 203021 | AY10: 200216 | AZ10: 198572 | BA10: 197598 | BB10: 197618 | BC10: 197431 | BD10: 197105 | BE10: 194984 | BF10: 194052 | BG10: 191353 | BH10: 188829 | BI10: 185112 | BJ10: 180222 | BK10: 173949 | BL10: 166605 | BM10: 158491 | BN10: 151310 | BO10: 144139 | BP10: 137827 | BQ10: 131008 | BR10: 125316 | BS10: 119163 | BT10: 112959 | BU10: 106877 | BV10: 101105 | BW10: 95248 | BX10: 89659 | BY10: 83989 | BZ10: 78212 | CA10: 72246 | CB10: 66950 | CC10: 62232 | CD10: 58328 | CE10: 54902 | CF10: 51503 | CG10: 47956 | CH10: 44318 | CI10: 40491 | CJ10: 36428 | CK10: 32598 | CL10: 29328 | CM10: 26280 | CN10: 23432 | CO10: 20531 | CP10: 17905 | CQ10: 15344 | CR10: 13101 | CS10: 10869 | CT10: 8754 | CU10: 6944 | CV10: 5380 | CW10: 4157 | CX10: 3185 | CY10: 2387 | CZ10: 1772 | DA10: 1303 | DB10: 994 | DC10: 3880 | DD10: 254961 | DE10: 259756 | DF10: 263118 | DG10: 266313 | DH10: 269609 | DI10: 272563 | DJ10: 276055 | DK10: 279396 | DL10: 283374 | DM10: 287406 | DN10: 291740 | DO10: 296246 | DP10: 297202 | DQ10: 298219 | DR10: 299635 | DS10: 302119 | DT10: 304723 | DU10: 308827 | DV10: 313178 | DW10: 317186 | DX10: 320927 | DY10: 321558 | DZ10: 322506 | EA10: 323518 | EB10: 322371 | EC10: 318788 | ED10: 313173 | EE10: 306505 | EF10: 299926 | EG10: 292849 | EH10: 287622 | EI10: 283326 | EJ10: 280401 | EK10: 277714 | EL10: 277528 | EM10: 277373 | EN10: 275696 | EO10: 272569 | EP10: 268359 | EQ10: 260561 | ER10: 253844 | ES10: 245784 | ET10: 239126 | EU10: 233835 | EV10: 231381 | EW10: 229945 | EX10: 229476 | EY10: 230405 | EZ10: 231750 | FA10: 230700 | FB10: 230852 | FC10: 229471 | FD10: 228566 | FE10: 225918 | FF10: 222863 | FG10: 218023 | FH10: 211302 | FI10: 204189 | FJ10: 196600 | FK10: 188660 | FL10: 182047 | FM10: 174886 | FN10: 168043 | FO10: 160237 | FP10: 152692 | FQ10: 144828 | FR10: 137347 | FS10: 130421 | FT10: 123662 | FU10: 116624 | FV10: 109791 | FW10: 102538 | FX10: 95757 | FY10: 89178 | FZ10: 83336 | GA10: 78400 | GB10: 74468 | GC10: 70896 | GD10: 67031 | GE10: 62848 | GF10: 58496 | GG10: 54049 | GH10: 49585 | GI10: 45117 | GJ10: 40603 | GK10: 36415 | GL10: 32633 | GM10: 28921 | GN10: 25421 | GO10: 22012 | GP10: 18749 | GQ10: 15393 | GR10: 12319 | GS10: 9784 | GT10: 7697 | GU10: 6082 | GV10: 4744 | GW10: 3638 | GX10: 2596 | GY10: 1725 | GZ10: 5570 | HA10: 522686 | HB10: 531415 | HC10: 538697 | HD10: 545485 | HE10: 551668 | HF10: 557289 | HG10: 564108 | HH10: 571276 | HI10: 579306 | HJ10: 587263 | HK10: 595527 | HL10: 604206 | HM10: 605802 | HN10: 607140 | HO10: 608143 | HP10: 611132 | HQ10: 614374 | HR10: 621168 | HS10: 624642 | HT10: 628812 | HU10: 633498 | HV10: 636239 | HW10: 638963 | HX10: 641245 | HY10: 638641 | HZ10: 629944 | IA10: 617589 | IB10: 603799 | IC10: 589653 | ID10: 575076 | IE10: 561352 | IF10: 551250 | IG10: 543269 | IH10: 536855 | II10: 534254 | IJ10: 531349 | IK10: 525868 | IL10: 519113 | IM10: 508858 | IN10: 493730 | IO10: 477987 | IP10: 462524 | IQ10: 447343 | IR10: 436856 | IS10: 431597 | IT10: 428517 | IU10: 427074 | IV10: 428023 | IW10: 429181 | IX10: 427805 | IY10: 425836 | IZ10: 423523 | JA10: 419919 | JB10: 414747 | JC10: 407975 | JD10: 398245 | JE10: 385251 | JF10: 370794 | JG10: 355091 | JH10: 339970 | JI10: 326186 | JJ10: 312713 | JK10: 299051 | JL10: 285553 | JM10: 271855 | JN10: 257787 | JO10: 244224 | JP10: 231526 | JQ10: 218910 | JR10: 206283 | JS10: 193780 | JT10: 180750 | JU10: 168003 | JV10: 156128 | JW10: 145568 | JX10: 136728 | JY10: 129370 | JZ10: 122399 | KA10: 114987 | KB10: 107166 | KC10: 98987 | KD10: 90477 | KE10: 82183 | KF10: 74445 | KG10: 66883 | KH10: 59847 | KI10: 53164 | KJ10: 46826 | KK10: 40765 | KL10: 35113 | KM10: 29618 | KN10: 24147 | KO10: 19263 | KP10: 15164 | KQ10: 11854 | KR10: 9267 | KS10: 7131 | KT10: 5410 | KU10: 3899 | KV10: 2719 | KW10: 9450
A11: Total Nacional | B11: 2018 | C11: Centros Poblados y Rural Disperso | D11: 11843973 | E11: 6163808 | F11: 5680165 | G11: 111886 | H11: 112733 | I11: 114233 | J11: 116189 | K11: 118018 | L11: 120287 | M11: 121987 | N11: 123959 | O11: 125744 | P11: 127610 | Q11: 129514 | R11: 131555 | S11: 131803 | T11: 131507 | U11: 130343 | V11: 127905 | W11: 125439 | X11: 122324 | Y11: 117186 | Z11: 111517 | AA11: 105883 | AB11: 100885 | AC11: 97528 | AD11: 94939 | AE11: 92159 | AF11: 88872 | AG11: 85784 | AH11: 83169 | AI11: 80929 | AJ11: 79061 | AK11: 77130 | AL11: 76128 | AM11: 75207 | AN11: 74839 | AO11: 74899 | AP11: 74918 | AQ11: 74683 | AR11: 74549 | AS11: 74090 | AT11: 73199 | AU11: 71546 | AV11: 70301 | AW11: 68494 | AX11: 67647 | AY11: 67276 | AZ11: 67032 | BA11: 66790 | BB11: 66624 | BC11: 66324 | BD11: 65855 | BE11: 64813 | BF11: 64033 | BG11: 62688 | BH11: 61600 | BI11: 60311 | BJ11: 58850 | BK11: 57096 | BL11: 55197 | BM11: 53029 | BN11: 51197 | BO11: 49307 | BP11: 47694 | BQ11: 45909 | BR11: 44413 | BS11: 42889 | BT11: 41398 | BU11: 39842 | BV11: 38199 | BW11: 36366 | BX11: 34705 | BY11: 32944 | BZ11: 30982 | CA11: 28842 | CB11: 26950 | CC11: 25195 | CD11: 23854 | CE11: 22552 | CF11: 21223 | CG11: 19748 | CH11: 18259 | CI11: 16587 | CJ11: 14701 | CK11: 12863 | CL11: 11349 | CM11: 10007 | CN11: 8835 | CO11: 7607 | CP11: 6474 | CQ11: 5443 | CR11: 4575 | CS11: 3749 | CT11: 2975 | CU11: 2344 | CV11: 1814 | CW11: 1389 | CX11: 1060 | CY11: 791 | CZ11: 592 | DA11: 438 | DB11: 345 | DC11: 1306 | DD11: 105462 | DE11: 107101 | DF11: 108341 | DG11: 109857 | DH11: 111788 | DI11: 114035 | DJ11: 115821 | DK11: 117174 | DL11: 118138 | DM11: 119471 | DN11: 121035 | DO11: 122659 | DP11: 122262 | DQ11: 121124 | DR11: 119536 | DS11: 116878 | DT11: 114173 | DU11: 110457 | DV11: 105793 | DW11: 101192 | DX11: 96991 | DY11: 92469 | DZ11: 89503 | EA11: 87452 | EB11: 85521 | EC11: 83270 | ED11: 80869 | EE11: 78702 | EF11: 76927 | EG11: 75290 | EH11: 74346 | EI11: 73563 | EJ11: 73142 | EK11: 72502 | EL11: 72451 | EM11: 72437 | EN11: 71975 | EO11: 71295 | EP11: 70220 | EQ11: 68272 | ER11: 66627 | ES11: 64682 | ET11: 63115 | EU11: 61613 | EV11: 60795 | EW11: 60154 | EX11: 59619 | EY11: 59283 | EZ11: 58843 | FA11: 57798 | FB11: 57079 | FC11: 55999 | FD11: 55118 | FE11: 53930 | FF11: 52803 | FG11: 51405 | FH11: 49795 | FI11: 48189 | FJ11: 46574 | FK11: 44772 | FL11: 43236 | FM11: 41558 | FN11: 40062 | FO11: 38477 | FP11: 36994 | FQ11: 35460 | FR11: 34026 | FS11: 32665 | FT11: 31319 | FU11: 29789 | FV11: 28254 | FW11: 26607 | FX11: 25090 | FY11: 23513 | FZ11: 22032 | GA11: 20733 | GB11: 19858 | GC11: 18998 | GD11: 17966 | GE11: 16744 | GF11: 15417 | GG11: 14119 | GH11: 12891 | GI11: 11635 | GJ11: 10327 | GK11: 9072 | GL11: 7986 | GM11: 6937 | GN11: 5967 | GO11: 5039 | GP11: 4217 | GQ11: 3404 | GR11: 2695 | GS11: 2137 | GT11: 1672 | GU11: 1330 | GV11: 1039 | GW11: 809 | GX11: 597 | GY11: 420 | GZ11: 1387 | HA11: 217348 | HB11: 219834 | HC11: 222574 | HD11: 226046 | HE11: 229806 | HF11: 234322 | HG11: 237808 | HH11: 241133 | HI11: 243882 | HJ11: 247081 | HK11: 250549 | HL11: 254214 | HM11: 254065 | HN11: 252631 | HO11: 249879 | HP11: 244783 | HQ11: 239612 | HR11: 232781 | HS11: 222979 | HT11: 212709 | HU11: 202874 | HV11: 193354 | HW11: 187031 | HX11: 182391 | HY11: 177680 | HZ11: 172142 | IA11: 166653 | IB11: 161871 | IC11: 157856 | ID11: 154351 | IE11: 151476 | IF11: 149691 | IG11: 148349 | IH11: 147341 | II11: 147350 | IJ11: 147355 | IK11: 146658 | IL11: 145844 | IM11: 144310 | IN11: 141471 | IO11: 138173 | IP11: 134983 | IQ11: 131609 | IR11: 129260 | IS11: 128071 | IT11: 127186 | IU11: 126409 | IV11: 125907 | IW11: 125167 | IX11: 123653 | IY11: 121892 | IZ11: 120032 | JA11: 117806 | JB11: 115530 | JC11: 113114 | JD11: 110255 | JE11: 106891 | JF11: 103386 | JG11: 99603 | JH11: 95969 | JI11: 92543 | JJ11: 89252 | JK11: 85971 | JL11: 82890 | JM11: 79883 | JN11: 76858 | JO11: 73868 | JP11: 70864 | JQ11: 67685 | JR11: 64494 | JS11: 61198 | JT11: 57589 | JU11: 53932 | JV11: 50463 | JW11: 47227 | JX11: 44587 | JY11: 42410 | JZ11: 40221 | KA11: 37714 | KB11: 35003 | KC11: 32004 | KD11: 28820 | KE11: 25754 | KF11: 22984 | KG11: 20334 | KH11: 17907 | KI11: 15593 | KJ11: 13411 | KK11: 11410 | KL11: 9614 | KM11: 7966 | KN11: 6379 | KO11: 5039 | KP11: 3951 | KQ11: 3061 | KR11: 2390 | KS11: 1830 | KT11: 1401 | KU11: 1035 | KV11: 765 | KW11: 2693
A12: Total Nacional | B12: 2018 | C12: Total | D12: 48258494 | E12: 23614164 | F12: 24644330 | G12: 379611 | H12: 384392 | I12: 389812 | J12: 395361 | K12: 400077 | L12: 405013 | M12: 410040 | N12: 415839 | O12: 421676 | P12: 427467 | Q12: 433301 | R12: 439515 | S12: 440403 | T12: 440428 | U12: 438851 | V12: 436918 | W12: 435090 | X12: 434665 | Y12: 428650 | Z12: 423143 | AA12: 418454 | AB12: 415566 | AC12: 413985 | AD12: 412666 | AE12: 408429 | AF12: 400028 | AG12: 390200 | AH12: 380463 | AI12: 370656 | AJ12: 361288 | AK12: 350860 | AL12: 344052 | AM12: 338075 | AN12: 333980 | AO12: 331625 | AP12: 328894 | AQ12: 324855 | AR12: 321093 | AS12: 314589 | AT12: 306368 | AU12: 295689 | AV12: 287041 | AW12: 276711 | AX12: 270668 | AY12: 267492 | AZ12: 265604 | BA12: 264388 | BB12: 264242 | BC12: 263755 | BD12: 262960 | BE12: 259797 | BF12: 258085 | BG12: 254041 | BH12: 250429 | BI12: 245423 | BJ12: 239072 | BK12: 231045 | BL12: 221802 | BM12: 211520 | BN12: 202507 | BO12: 193446 | BP12: 185521 | BQ12: 176917 | BR12: 169729 | BS12: 162052 | BT12: 154357 | BU12: 146719 | BV12: 139304 | BW12: 131614 | BX12: 124364 | BY12: 116933 | BZ12: 109194 | CA12: 101088 | CB12: 93900 | CC12: 87427 | CD12: 82182 | CE12: 77454 | CF12: 72726 | CG12: 67704 | CH12: 62577 | CI12: 57078 | CJ12: 51129 | CK12: 45461 | CL12: 40677 | CM12: 36287 | CN12: 32267 | CO12: 28138 | CP12: 24379 | CQ12: 20787 | CR12: 17676 | CS12: 14618 | CT12: 11729 | CU12: 9288 | CV12: 7194 | CW12: 5546 | CX12: 4245 | CY12: 3178 | CZ12: 2364 | DA12: 1741 | DB12: 1339 | DC12: 5186 | DD12: 360423 | DE12: 366857 | DF12: 371459 | DG12: 376170 | DH12: 381397 | DI12: 386598 | DJ12: 391876 | DK12: 396570 | DL12: 401512 | DM12: 406877 | DN12: 412775 | DO12: 418905 | DP12: 419464 | DQ12: 419343 | DR12: 419171 | DS12: 418997 | DT12: 418896 | DU12: 419284 | DV12: 418971 | DW12: 418378 | DX12: 417918 | DY12: 414027 | DZ12: 412009 | EA12: 410970 | EB12: 407892 | EC12: 402058 | ED12: 394042 | EE12: 385207 | EF12: 376853 | EG12: 368139 | EH12: 361968 | EI12: 356889 | EJ12: 353543 | EK12: 350216 | EL12: 349979 | EM12: 349810 | EN12: 347671 | EO12: 343864 | EP12: 338579 | EQ12: 328833 | ER12: 320471 | ES12: 310466 | ET12: 302241 | EU12: 295448 | EV12: 292176 | EW12: 290099 | EX12: 289095 | EY12: 289688 | EZ12: 290593 | FA12: 288498 | FB12: 287931 | FC12: 285470 | FD12: 283684 | FE12: 279848 | FF12: 275666 | FG12: 269428 | FH12: 261097 | FI12: 252378 | FJ12: 243174 | FK12: 233432 | FL12: 225283 | FM12: 216444 | FN12: 208105 | FO12: 198714 | FP12: 189686 | FQ12: 180288 | FR12: 171373 | FS12: 163086 | FT12: 154981 | FU12: 146413 | FV12: 138045 | FW12: 129145 | FX12: 120847 | FY12: 112691 | FZ12: 105368 | GA12: 99133 | GB12: 94326 | GC12: 89894 | GD12: 84997 | GE12: 79592 | GF12: 73913 | GG12: 68168 | GH12: 62476 | GI12: 56752 | GJ12: 50930 | GK12: 45487 | GL12: 40619 | GM12: 35858 | GN12: 31388 | GO12: 27051 | GP12: 22966 | GQ12: 18797 | GR12: 15014 | GS12: 11921 | GT12: 9369 | GU12: 7412 | GV12: 5783 | GW12: 4447 | GX12: 3193 | GY12: 2145 | GZ12: 6957 | HA12: 740034 | HB12: 751249 | HC12: 761271 | HD12: 771531 | HE12: 781474 | HF12: 791611 | HG12: 801916 | HH12: 812409 | HI12: 823188 | HJ12: 834344 | HK12: 846076 | HL12: 858420 | HM12: 859867 | HN12: 859771 | HO12: 858022 | HP12: 855915 | HQ12: 853986 | HR12: 853949 | HS12: 847621 | HT12: 841521 | HU12: 836372 | HV12: 829593 | HW12: 825994 | HX12: 823636 | HY12: 816321 | HZ12: 802086 | IA12: 784242 | IB12: 765670 | IC12: 747509 | ID12: 729427 | IE12: 712828 | IF12: 700941 | IG12: 691618 | IH12: 684196 | II12: 681604 | IJ12: 678704 | IK12: 672526 | IL12: 664957 | IM12: 653168 | IN12: 635201 | IO12: 616160 | IP12: 597507 | IQ12: 578952 | IR12: 566116 | IS12: 559668 | IT12: 555703 | IU12: 553483 | IV12: 553930 | IW12: 554348 | IX12: 551458 | IY12: 547728 | IZ12: 543555 | JA12: 537725 | JB12: 530277 | JC12: 521089 | JD12: 508500 | JE12: 492142 | JF12: 474180 | JG12: 454694 | JH12: 435939 | JI12: 418729 | JJ12: 401965 | JK12: 385022 | JL12: 368443 | JM12: 351738 | JN12: 334645 | JO12: 318092 | JP12: 302390 | JQ12: 286595 | JR12: 270777 | JS12: 254978 | JT12: 238339 | JU12: 221935 | JV12: 206591 | JW12: 192795 | JX12: 181315 | JY12: 171780 | JZ12: 162620 | KA12: 152701 | KB12: 142169 | KC12: 130991 | KD12: 119297 | KE12: 107937 | KF12: 97429 | KG12: 87217 | KH12: 77754 | KI12: 68757 | KJ12: 60237 | KK12: 52175 | KL12: 44727 | KM12: 37584 | KN12: 30526 | KO12: 24302 | KP12: 19115 | KQ12: 14915 | KR12: 11657 | KS12: 8961 | KT12: 6811 | KU12: 4934 | KV12: 3484 | KW12: 12143
A13: Total Nacional | B13: 2019 | C13: Cabecera | D13: 37219289 | E13: 17846792 | F13: 19372497 | G13: 267420 | H13: 273412 | I13: 276783 | J13: 280107 | K13: 283243 | L13: 285528 | M13: 288638 | N13: 291776 | O13: 295702 | P13: 299371 | Q13: 303080 | R13: 306819 | S13: 310831 | T13: 311818 | U13: 312382 | V13: 312941 | W13: 313480 | X13: 314844 | Y13: 318375 | Z13: 318349 | AA13: 319239 | AB13: 320743 | AC13: 323189 | AD13: 325154 | AE13: 326387 | AF13: 324690 | AG13: 319183 | AH13: 311979 | AI13: 304328 | AJ13: 296216 | AK13: 288201 | AL13: 279261 | AM13: 273014 | AN13: 267519 | AO13: 263345 | AP13: 260494 | AQ13: 257351 | AR13: 253161 | AS13: 249155 | AT13: 242795 | AU13: 235228 | AV13: 226006 | AW13: 218381 | AX13: 209703 | AY13: 204397 | AZ13: 201481 | BA13: 199739 | BB13: 198666 | BC13: 198565 | BD13: 198256 | BE13: 197728 | BF13: 195409 | BG13: 194280 | BH13: 191392 | BI13: 188644 | BJ13: 184685 | BK13: 179559 | BL13: 173079 | BM13: 165544 | BN13: 157278 | BO13: 149972 | BP13: 142674 | BQ13: 136215 | BR13: 129264 | BS13: 123419 | BT13: 117160 | BU13: 110864 | BV13: 104704 | BW13: 98866 | BX13: 92912 | BY13: 87247 | BZ13: 81515 | CA13: 75694 | CB13: 69719 | CC13: 64407 | CD13: 59670 | CE13: 55710 | CF13: 52208 | CG13: 48758 | CH13: 45165 | CI13: 41506 | CJ13: 37696 | CK13: 33697 | CL13: 29932 | CM13: 26723 | CN13: 23753 | CO13: 20978 | CP13: 18214 | CQ13: 15703 | CR13: 13312 | CS13: 11224 | CT13: 9194 | CU13: 7303 | CV13: 5723 | CW13: 4379 | CX13: 3337 | CY13: 2535 | CZ13: 1873 | DA13: 1379 | DB13: 1011 | DC13: 2854 | DD13: 254999 | DE13: 260283 | DF13: 264552 | DG13: 267382 | DH13: 270177 | DI13: 273026 | DJ13: 276279 | DK13: 279839 | DL13: 283400 | DM13: 287087 | DN13: 290916 | DO13: 295119 | DP13: 299733 | DQ13: 300977 | DR13: 302307 | DS13: 304775 | DT13: 307394 | DU13: 310927 | DV13: 316085 | DW13: 321412 | DX13: 326197 | DY13: 330391 | DZ13: 331191 | EA13: 332066 | EB13: 332781 | EC13: 331191 | ED13: 327067 | EE13: 320862 | EF13: 313610 | EG13: 306490 | EH13: 298954 | EI13: 293329 | EJ13: 288664 | EK13: 285372 | EL13: 282320 | EM13: 281781 | EN13: 281279 | EO13: 279284 | EP13: 275854 | EQ13: 271351 | ER13: 263341 | ES13: 256415 | ET13: 248165 | EU13: 241338 | EV13: 235938 | EW13: 233383 | EX13: 231842 | EY13: 231240 | EZ13: 232039 | FA13: 233224 | FB13: 231985 | FC13: 231923 | FD13: 230371 | FE13: 229275 | FF13: 226417 | FG13: 223131 | FH13: 218079 | FI13: 211180 | FJ13: 203896 | FK13: 196171 | FL13: 188107 | FM13: 181350 | FN13: 174013 | FO13: 166999 | FP13: 159035 | FQ13: 151366 | FR13: 143384 | FS13: 135784 | FT13: 128731 | FU13: 121840 | FV13: 114670 | FW13: 107732 | FX13: 100409 | FY13: 93550 | FZ13: 86908 | GA13: 80968 | GB13: 75901 | GC13: 71808 | GD13: 68068 | GE13: 64054 | GF13: 59740 | GG13: 55260 | GH13: 50723 | GI13: 46187 | GJ13: 41694 | GK13: 37259 | GL13: 33104 | GM13: 29380 | GN13: 25755 | GO13: 22367 | GP13: 19105 | GQ13: 16052 | GR13: 12995 | GS13: 10255 | GT13: 8024 | GU13: 6212 | GV13: 4830 | GW13: 3709 | GX13: 2805 | GY13: 1981 | GZ13: 4327 | HA13: 522419 | HB13: 533695 | HC13: 541335 | HD13: 547489 | HE13: 553420 | HF13: 558554 | HG13: 564917 | HH13: 571615 | HI13: 579102 | HJ13: 586458 | HK13: 593996 | HL13: 601938 | HM13: 610564 | HN13: 612795 | HO13: 614689 | HP13: 617716 | HQ13: 620874 | HR13: 625771 | HS13: 634460 | HT13: 639761 | HU13: 645436 | HV13: 651134 | HW13: 654380 | HX13: 657220 | HY13: 659168 | HZ13: 655881 | IA13: 646250 | IB13: 632841 | IC13: 617938 | ID13: 602706 | IE13: 587155 | IF13: 572590 | IG13: 561678 | IH13: 552891 | II13: 545665 | IJ13: 542275 | IK13: 538630 | IL13: 532445 | IM13: 525009 | IN13: 514146 | IO13: 498569 | IP13: 482421 | IQ13: 466546 | IR13: 451041 | IS13: 440335 | IT13: 434864 | IU13: 431581 | IV13: 429906 | IW13: 430604 | IX13: 431480 | IY13: 429713 | IZ13: 427332 | JA13: 424651 | JB13: 420667 | JC13: 415061 | JD13: 407816 | JE13: 397638 | JF13: 384259 | JG13: 369440 | JH13: 353449 | JI13: 338079 | JJ13: 324024 | JK13: 310228 | JL13: 296263 | JM13: 282454 | JN13: 268526 | JO13: 254248 | JP13: 240488 | JQ13: 227597 | JR13: 214752 | JS13: 201917 | JT13: 189247 | JU13: 176103 | JV13: 163269 | JW13: 151315 | JX13: 140638 | JY13: 131611 | JZ13: 124016 | KA13: 116826 | KB13: 109219 | KC13: 101246 | KD13: 92956 | KE13: 84420 | KF13: 76119 | KG13: 68417 | KH13: 61012 | KI13: 54082 | KJ13: 47594 | KK13: 41458 | KL13: 35679 | KM13: 30329 | KN13: 25246 | KO13: 20298 | KP13: 15978 | KQ13: 12403 | KR13: 9549 | KS13: 7365 | KT13: 5582 | KU13: 4184 | KV13: 2992 | KW13: 7181
A14: Total Nacional | B14: 2019 | C14: Centros Poblados y Rural Disperso | D14: 12047237 | E14: 6270851 | F14: 5776386 | G14: 112272 | H14: 113270 | I14: 114410 | J14: 116137 | K14: 118171 | L14: 120243 | M14: 121728 | N14: 123290 | O14: 124863 | P14: 126739 | Q14: 128549 | R14: 130399 | S14: 132359 | T14: 132075 | U14: 131427 | V14: 129345 | W14: 127159 | X14: 124534 | Y14: 121353 | Z14: 116275 | AA14: 110789 | AB14: 105383 | AC14: 100634 | AD14: 97448 | AE14: 95030 | AF14: 92451 | AG14: 89378 | AH14: 86480 | AI14: 84039 | AJ14: 81945 | AK14: 80151 | AL14: 78236 | AM14: 77218 | AN14: 76297 | AO14: 75937 | AP14: 76005 | AQ14: 76005 | AR14: 75775 | AS14: 75642 | AT14: 75151 | AU14: 74174 | AV14: 72429 | AW14: 71117 | AX14: 69215 | AY14: 68220 | AZ14: 67699 | BA14: 67302 | BB14: 66910 | BC14: 66611 | BD14: 66191 | BE14: 65677 | BF14: 64606 | BG14: 63787 | BH14: 62410 | BI14: 61316 | BJ14: 60049 | BK14: 58612 | BL14: 56874 | BM14: 54977 | BN14: 52798 | BO14: 50922 | BP14: 48984 | BQ14: 47339 | BR14: 45524 | BS14: 43990 | BT14: 42400 | BU14: 40823 | BV14: 39186 | BW14: 37447 | BX14: 35559 | BY14: 33828 | BZ14: 32003 | CA14: 29978 | CB14: 27788 | CC14: 25832 | CD14: 24016 | CE14: 22613 | CF14: 21253 | CG14: 19864 | CH14: 18361 | CI14: 16855 | CJ14: 15200 | CK14: 13360 | CL14: 11595 | CM14: 10137 | CN14: 8850 | CO14: 7743 | CP14: 6589 | CQ14: 5559 | CR14: 4618 | CS14: 3843 | CT14: 3110 | CU14: 2447 | CV14: 1901 | CW14: 1450 | CX14: 1103 | CY14: 826 | CZ14: 617 | DA14: 462 | DB14: 342 | DC14: 968 | DD14: 106191 | DE14: 106731 | DF14: 108669 | DG14: 110128 | DH14: 111719 | DI14: 113786 | DJ14: 115429 | DK14: 116860 | DL14: 117720 | DM14: 118718 | DN14: 120011 | DO14: 121482 | DP14: 122787 | DQ14: 121950 | DR14: 120445 | DS14: 117948 | DT14: 115639 | DU14: 112880 | DV14: 109242 | DW14: 104791 | DX14: 100439 | DY14: 96524 | DZ14: 92283 | EA14: 89555 | EB14: 87730 | EC14: 86003 | ED14: 83941 | EE14: 81715 | EF14: 79679 | EG14: 77968 | EH14: 76326 | EI14: 75308 | EJ14: 74441 | EK14: 73945 | EL14: 73255 | EM14: 73155 | EN14: 73096 | EO14: 72591 | EP14: 71870 | EQ14: 70763 | ER14: 68741 | ES14: 67022 | ET14: 65018 | EU14: 63380 | EV14: 61758 | EW14: 60814 | EX14: 60059 | EY14: 59443 | EZ14: 59022 | FA14: 58528 | FB14: 57484 | FC14: 56772 | FD14: 55672 | FE14: 54788 | FF14: 53627 | FG14: 52543 | FH14: 51182 | FI14: 49584 | FJ14: 47983 | FK14: 46346 | FL14: 44514 | FM14: 42955 | FN14: 41298 | FO14: 39798 | FP14: 38214 | FQ14: 36696 | FR14: 35128 | FS14: 33648 | FT14: 32247 | FU14: 30864 | FV14: 29305 | FW14: 27721 | FX14: 26015 | FY14: 24432 | FZ14: 22799 | GA14: 21267 | GB14: 19935 | GC14: 19008 | GD14: 18085 | GE14: 16997 | GF14: 15739 | GG14: 14410 | GH14: 13113 | GI14: 11891 | GJ14: 10642 | GK14: 9367 | GL14: 8162 | GM14: 7102 | GN14: 6108 | GO14: 5199 | GP14: 4359 | GQ14: 3600 | GR14: 2868 | GS14: 2239 | GT14: 1750 | GU14: 1357 | GV14: 1067 | GW14: 822 | GX14: 638 | GY14: 472 | GZ14: 1076 | HA14: 218463 | HB14: 220001 | HC14: 223079 | HD14: 226265 | HE14: 229890 | HF14: 234029 | HG14: 237157 | HH14: 240150 | HI14: 242583 | HJ14: 245457 | HK14: 248560 | HL14: 251881 | HM14: 255146 | HN14: 254025 | HO14: 251872 | HP14: 247293 | HQ14: 242798 | HR14: 237414 | HS14: 230595 | HT14: 221066 | HU14: 211228 | HV14: 201907 | HW14: 192917 | HX14: 187003 | HY14: 182760 | HZ14: 178454 | IA14: 173319 | IB14: 168195 | IC14: 163718 | ID14: 159913 | IE14: 156477 | IF14: 153544 | IG14: 151659 | IH14: 150242 | II14: 149192 | IJ14: 149160 | IK14: 149101 | IL14: 148366 | IM14: 147512 | IN14: 145914 | IO14: 142915 | IP14: 139451 | IQ14: 136135 | IR14: 132595 | IS14: 129978 | IT14: 128513 | IU14: 127361 | IV14: 126353 | IW14: 125633 | IX14: 124719 | IY14: 123161 | IZ14: 121378 | JA14: 119459 | JB14: 117198 | JC14: 114943 | JD14: 112592 | JE14: 109794 | JF14: 106458 | JG14: 102960 | JH14: 99144 | JI14: 95436 | JJ14: 91939 | JK14: 88637 | JL14: 85322 | JM14: 82204 | JN14: 79096 | JO14: 75951 | JP14: 72834 | JQ14: 69694 | JR14: 66423 | JS14: 63133 | JT14: 59724 | JU14: 55993 | JV14: 52220 | JW14: 48631 | JX14: 45283 | JY14: 42548 | JZ14: 40261 | KA14: 37949 | KB14: 35358 | KC14: 32594 | KD14: 29610 | KE14: 26473 | KF14: 23486 | KG14: 20779 | KH14: 18217 | KI14: 15905 | KJ14: 13691 | KK14: 11667 | KL14: 9817 | KM14: 8202 | KN14: 6710 | KO14: 5315 | KP14: 4140 | KQ14: 3200 | KR14: 2460 | KS14: 1893 | KT14: 1439 | KU14: 1100 | KV14: 814 | KW14: 2044
A15: Total Nacional | B15: 2019 | C15: Total | D15: 49266526 | E15: 24117643 | F15: 25148883 | G15: 379692 | H15: 386682 | I15: 391193 | J15: 396244 | K15: 401414 | L15: 405771 | M15: 410366 | N15: 415066 | O15: 420565 | P15: 426110 | Q15: 431629 | R15: 437218 | S15: 443190 | T15: 443893 | U15: 443809 | V15: 442286 | W15: 440639 | X15: 439378 | Y15: 439728 | Z15: 434624 | AA15: 430028 | AB15: 426126 | AC15: 423823 | AD15: 422602 | AE15: 421417 | AF15: 417141 | AG15: 408561 | AH15: 398459 | AI15: 388367 | AJ15: 378161 | AK15: 368352 | AL15: 357497 | AM15: 350232 | AN15: 343816 | AO15: 339282 | AP15: 336499 | AQ15: 333356 | AR15: 328936 | AS15: 324797 | AT15: 317946 | AU15: 309402 | AV15: 298435 | AW15: 289498 | AX15: 278918 | AY15: 272617 | AZ15: 269180 | BA15: 267041 | BB15: 265576 | BC15: 265176 | BD15: 264447 | BE15: 263405 | BF15: 260015 | BG15: 258067 | BH15: 253802 | BI15: 249960 | BJ15: 244734 | BK15: 238171 | BL15: 229953 | BM15: 220521 | BN15: 210076 | BO15: 200894 | BP15: 191658 | BQ15: 183554 | BR15: 174788 | BS15: 167409 | BT15: 159560 | BU15: 151687 | BV15: 143890 | BW15: 136313 | BX15: 128471 | BY15: 121075 | BZ15: 113518 | CA15: 105672 | CB15: 97507 | CC15: 90239 | CD15: 83686 | CE15: 78323 | CF15: 73461 | CG15: 68622 | CH15: 63526 | CI15: 58361 | CJ15: 52896 | CK15: 47057 | CL15: 41527 | CM15: 36860 | CN15: 32603 | CO15: 28721 | CP15: 24803 | CQ15: 21262 | CR15: 17930 | CS15: 15067 | CT15: 12304 | CU15: 9750 | CV15: 7624 | CW15: 5829 | CX15: 4440 | CY15: 3361 | CZ15: 2490 | DA15: 1841 | DB15: 1353 | DC15: 3822 | DD15: 361190 | DE15: 367014 | DF15: 373221 | DG15: 377510 | DH15: 381896 | DI15: 386812 | DJ15: 391708 | DK15: 396699 | DL15: 401120 | DM15: 405805 | DN15: 410927 | DO15: 416601 | DP15: 422520 | DQ15: 422927 | DR15: 422752 | DS15: 422723 | DT15: 423033 | DU15: 423807 | DV15: 425327 | DW15: 426203 | DX15: 426636 | DY15: 426915 | DZ15: 423474 | EA15: 421621 | EB15: 420511 | EC15: 417194 | ED15: 411008 | EE15: 402577 | EF15: 393289 | EG15: 384458 | EH15: 375280 | EI15: 368637 | EJ15: 363105 | EK15: 359317 | EL15: 355575 | EM15: 354936 | EN15: 354375 | EO15: 351875 | EP15: 347724 | EQ15: 342114 | ER15: 332082 | ES15: 323437 | ET15: 313183 | EU15: 304718 | EV15: 297696 | EW15: 294197 | EX15: 291901 | EY15: 290683 | EZ15: 291061 | FA15: 291752 | FB15: 289469 | FC15: 288695 | FD15: 286043 | FE15: 284063 | FF15: 280044 | FG15: 275674 | FH15: 269261 | FI15: 260764 | FJ15: 251879 | FK15: 242517 | FL15: 232621 | FM15: 224305 | FN15: 215311 | FO15: 206797 | FP15: 197249 | FQ15: 188062 | FR15: 178512 | FS15: 169432 | FT15: 160978 | FU15: 152704 | FV15: 143975 | FW15: 135453 | FX15: 126424 | FY15: 117982 | FZ15: 109707 | GA15: 102235 | GB15: 95836 | GC15: 90816 | GD15: 86153 | GE15: 81051 | GF15: 75479 | GG15: 69670 | GH15: 63836 | GI15: 58078 | GJ15: 52336 | GK15: 46626 | GL15: 41266 | GM15: 36482 | GN15: 31863 | GO15: 27566 | GP15: 23464 | GQ15: 19652 | GR15: 15863 | GS15: 12494 | GT15: 9774 | GU15: 7569 | GV15: 5897 | GW15: 4531 | GX15: 3443 | GY15: 2453 | GZ15: 5403 | HA15: 740882 | HB15: 753696 | HC15: 764414 | HD15: 773754 | HE15: 783310 | HF15: 792583 | HG15: 802074 | HH15: 811765 | HI15: 821685 | HJ15: 831915 | HK15: 842556 | HL15: 853819 | HM15: 865710 | HN15: 866820 | HO15: 866561 | HP15: 865009 | HQ15: 863672 | HR15: 863185 | HS15: 865055 | HT15: 860827 | HU15: 856664 | HV15: 853041 | HW15: 847297 | HX15: 844223 | HY15: 841928 | HZ15: 834335 | IA15: 819569 | IB15: 801036 | IC15: 781656 | ID15: 762619 | IE15: 743632 | IF15: 726134 | IG15: 713337 | IH15: 703133 | II15: 694857 | IJ15: 691435 | IK15: 687731 | IL15: 680811 | IM15: 672521 | IN15: 660060 | IO15: 641484 | IP15: 621872 | IQ15: 602681 | IR15: 583636 | IS15: 570313 | IT15: 563377 | IU15: 558942 | IV15: 556259 | IW15: 556237 | IX15: 556199 | IY15: 552874 | IZ15: 548710 | JA15: 544110 | JB15: 537865 | JC15: 530004 | JD15: 520408 | JE15: 507432 | JF15: 490717 | JG15: 472400 | JH15: 452593 | JI15: 433515 | JJ15: 415963 | JK15: 398865 | JL15: 381585 | JM15: 364658 | JN15: 347622 | JO15: 330199 | JP15: 313322 | JQ15: 297291 | JR15: 281175 | JS15: 265050 | JT15: 248971 | JU15: 232096 | JV15: 215489 | JW15: 199946 | JX15: 185921 | JY15: 174159 | JZ15: 164277 | KA15: 154775 | KB15: 144577 | KC15: 133840 | KD15: 122566 | KE15: 110893 | KF15: 99605 | KG15: 89196 | KH15: 79229 | KI15: 69987 | KJ15: 61285 | KK15: 53125 | KL15: 45496 | KM15: 38531 | KN15: 31956 | KO15: 25613 | KP15: 20118 | KQ15: 15603 | KR15: 12009 | KS15: 9258 | KT15: 7021 | KU15: 5284 | KV15: 3806 | KW15: 9225
A16: Total Nacional | B16: 2020 | C16: Cabecera | D16: 38130362 | E16: 18296255 | F16: 19834107 | G16: 272089 | H16: 274272 | I16: 279600 | J16: 282319 | K16: 285125 | L16: 287612 | M16: 290288 | N16: 293163 | O16: 296353 | P16: 299864 | Q16: 303276 | R16: 306767 | S16: 310322 | T16: 314669 | U16: 315884 | V16: 317451 | W16: 318102 | X16: 319481 | Y16: 321861 | Z16: 326448 | AA16: 327331 | AB16: 328919 | AC16: 330867 | AD16: 333515 | AE16: 335462 | AF16: 336436 | AG16: 334290 | AH16: 328248 | AI16: 320443 | AJ16: 312158 | AK16: 303453 | AL16: 294891 | AM16: 285461 | AN16: 278706 | AO16: 272693 | AP16: 268028 | AQ16: 264720 | AR16: 261125 | AS16: 256507 | AT16: 252118 | AU16: 245464 | AV16: 237637 | AW16: 228174 | AX16: 220343 | AY16: 211529 | AZ16: 206106 | BA16: 203075 | BB16: 201198 | BC16: 199991 | BD16: 199748 | BE16: 199219 | BF16: 198456 | BG16: 195935 | BH16: 194587 | BI16: 191464 | BJ16: 188443 | BK16: 184225 | BL16: 178855 | BM16: 172156 | BN16: 164444 | BO16: 156048 | BP16: 148595 | BQ16: 141153 | BR16: 134544 | BS16: 127439 | BT16: 121474 | BU16: 115107 | BV16: 108728 | BW16: 102494 | BX16: 96551 | BY16: 90514 | BZ16: 84775 | CA16: 78979 | CB16: 73143 | CC16: 67150 | CD16: 61836 | CE16: 57068 | CF16: 53064 | CG16: 49499 | CH16: 45991 | CI16: 42376 | CJ16: 38712 | CK16: 34929 | CL16: 31004 | CM16: 27338 | CN16: 24210 | CO16: 21320 | CP16: 18652 | CQ16: 16025 | CR16: 13669 | CS16: 11449 | CT16: 9527 | CU16: 7707 | CV16: 6051 | CW16: 4674 | CX16: 3546 | CY16: 2674 | CZ16: 2007 | DA16: 1475 | DB16: 1089 | DC16: 2303 | DD16: 259426 | DE16: 261387 | DF16: 266076 | DG16: 269757 | DH16: 272146 | DI16: 274447 | DJ16: 277555 | DK16: 280838 | DL16: 284582 | DM16: 287816 | DN16: 291263 | DO16: 294937 | DP16: 299220 | DQ16: 304107 | DR16: 305665 | DS16: 308069 | DT16: 310750 | DU16: 314439 | DV16: 319267 | DW16: 325641 | DX16: 331907 | DY16: 337270 | DZ16: 341688 | EA16: 342402 | EB16: 342960 | EC16: 343179 | ED16: 340984 | EE16: 336199 | EF16: 329321 | EG16: 321456 | EH16: 313790 | EI16: 305785 | EJ16: 299715 | EK16: 294625 | EL16: 290913 | EM16: 287467 | EN16: 286524 | EO16: 285663 | EP16: 283297 | EQ16: 279543 | ER16: 274765 | ES16: 266518 | ET16: 259354 | EU16: 250903 | EV16: 243932 | EW16: 238413 | EX16: 235731 | EY16: 234025 | EZ16: 233275 | FA16: 233898 | FB16: 234865 | FC16: 233399 | FD16: 233138 | FE16: 231385 | FF16: 230051 | FG16: 226943 | FH16: 223413 | FI16: 218159 | FJ16: 211069 | FK16: 203628 | FL16: 195761 | FM16: 187546 | FN16: 180601 | FO16: 173079 | FP16: 165883 | FQ16: 157779 | FR16: 149979 | FS16: 141870 | FT16: 134140 | FU16: 126943 | FV16: 119901 | FW16: 112625 | FX16: 105592 | FY16: 98191 | FZ16: 91250 | GA16: 84523 | GB16: 78478 | GC16: 73282 | GD16: 69035 | GE16: 65133 | GF16: 60974 | GG16: 56513 | GH16: 51944 | GI16: 47327 | GJ16: 42763 | GK16: 38326 | GL16: 33948 | GM16: 29877 | GN16: 26233 | GO16: 22726 | GP16: 19480 | GQ16: 16414 | GR16: 13599 | GS16: 10862 | GT16: 8446 | GU16: 6517 | GV16: 4970 | GW16: 3815 | GX16: 2888 | GY16: 2156 | GZ16: 3798 | HA16: 531515 | HB16: 535659 | HC16: 545676 | HD16: 552076 | HE16: 557271 | HF16: 562059 | HG16: 567843 | HH16: 574001 | HI16: 580935 | HJ16: 587680 | HK16: 594539 | HL16: 601704 | HM16: 609542 | HN16: 618776 | HO16: 621549 | HP16: 625520 | HQ16: 628852 | HR16: 633920 | HS16: 641128 | HT16: 652089 | HU16: 659238 | HV16: 666189 | HW16: 672555 | HX16: 675917 | HY16: 678422 | HZ16: 679615 | IA16: 675274 | IB16: 664447 | IC16: 649764 | ID16: 633614 | IE16: 617243 | IF16: 600676 | IG16: 585176 | IH16: 573331 | II16: 563606 | IJ16: 555495 | IK16: 551244 | IL16: 546788 | IM16: 539804 | IN16: 531661 | IO16: 520229 | IP16: 504155 | IQ16: 487528 | IR16: 471246 | IS16: 455461 | IT16: 444519 | IU16: 438806 | IV16: 435223 | IW16: 433266 | IX16: 433646 | IY16: 434084 | IZ16: 431855 | JA16: 429073 | JB16: 425972 | JC16: 421515 | JD16: 415386 | JE16: 407638 | JF16: 397014 | JG16: 383225 | JH16: 368072 | JI16: 351809 | JJ16: 336141 | JK16: 321754 | JL16: 307623 | JM16: 293322 | JN16: 279253 | JO16: 265086 | JP16: 250598 | JQ16: 236634 | JR16: 223494 | JS16: 210415 | JT16: 197400 | JU16: 184571 | JV16: 171334 | JW16: 158400 | JX16: 146359 | JY16: 135546 | JZ16: 126346 | KA16: 118534 | KB16: 111124 | KC16: 103350 | KD16: 95225 | KE16: 86873 | KF16: 78331 | KG16: 70101 | KH16: 62536 | KI16: 55268 | KJ16: 48529 | KK16: 42258 | KL16: 36395 | KM16: 30929 | KN16: 25941 | KO16: 21306 | KP16: 16913 | KQ16: 13120 | KR16: 10063 | KS16: 7644 | KT16: 5822 | KU16: 4363 | KV16: 3245 | KW16: 6101
A17: Total Nacional | B17: 2020 | C17: Centros Poblados y Rural Disperso | D17: 12260428 | E17: 6383485 | F17: 5876943 | G17: 113511 | H17: 113849 | I17: 115140 | J17: 116488 | K17: 118285 | L17: 120545 | M17: 121819 | N17: 123152 | O17: 124313 | P17: 125956 | Q17: 127776 | R17: 129512 | S17: 131278 | T17: 132687 | U17: 132056 | V17: 130486 | W17: 128660 | X17: 126323 | Y17: 123626 | Z17: 120464 | AA17: 115555 | AB17: 110299 | AC17: 105164 | AD17: 100642 | AE17: 97657 | AF17: 95443 | AG17: 93074 | AH17: 90205 | AI17: 87488 | AJ17: 85202 | AK17: 83182 | AL17: 81401 | AM17: 79458 | AN17: 78432 | AO17: 77517 | AP17: 77153 | AQ17: 77199 | AR17: 77190 | AS17: 76954 | AT17: 76788 | AU17: 76209 | AV17: 75130 | AW17: 73306 | AX17: 71883 | AY17: 69835 | AZ17: 68671 | BA17: 67991 | BB17: 67442 | BC17: 66911 | BD17: 66485 | BE17: 66014 | BF17: 65470 | BG17: 64356 | BH17: 63496 | BI17: 62116 | BJ17: 61047 | BK17: 59796 | BL17: 58381 | BM17: 56646 | BN17: 54736 | BO17: 52515 | BP17: 50592 | BQ17: 48627 | BR17: 46942 | BS17: 45098 | BT17: 43498 | BU17: 41828 | BV17: 40165 | BW17: 38429 | BX17: 36627 | BY17: 34682 | BZ17: 32880 | CA17: 30986 | CB17: 28891 | CC17: 26656 | CD17: 24648 | CE17: 22786 | CF17: 21324 | CG17: 19918 | CH17: 18489 | CI17: 16966 | CJ17: 15460 | CK17: 13838 | CL17: 12059 | CM17: 10375 | CN17: 8982 | CO17: 7772 | CP17: 6730 | CQ17: 5667 | CR17: 4730 | CS17: 3889 | CT17: 3202 | CU17: 2565 | CV17: 1983 | CW17: 1536 | CX17: 1152 | CY17: 870 | CZ17: 649 | DA17: 487 | DB17: 363 | DC17: 779 | DD17: 107349 | DE17: 107640 | DF17: 108474 | DG17: 110616 | DH17: 112139 | DI17: 113850 | DJ17: 115299 | DK17: 116581 | DL17: 117500 | DM17: 118385 | DN17: 119338 | DO17: 120530 | DP17: 121683 | DQ17: 122531 | DR17: 121314 | DS17: 118907 | DT17: 116772 | DU17: 114421 | DV17: 111709 | DW17: 108253 | DX17: 104065 | DY17: 100011 | DZ17: 96380 | EA17: 92422 | EB17: 89948 | EC17: 88336 | ED17: 86801 | EE17: 84906 | EF17: 82815 | EG17: 80841 | EH17: 79114 | EI17: 77400 | EJ17: 76294 | EK17: 75347 | EL17: 74776 | EM17: 74025 | EN17: 73880 | EO17: 73755 | EP17: 73217 | EQ17: 72451 | ER17: 71254 | ES17: 69158 | ET17: 67369 | EU17: 65284 | EV17: 63529 | EW17: 61778 | EX17: 60716 | EY17: 59883 | EZ17: 59180 | FA17: 58701 | FB17: 58199 | FC17: 57161 | FD17: 56433 | FE17: 55324 | FF17: 54468 | FG17: 53352 | FH17: 52307 | FI17: 50952 | FJ17: 49365 | FK17: 47743 | FL17: 46076 | FM17: 44224 | FN17: 42680 | FO17: 41025 | FP17: 39530 | FQ17: 37914 | FR17: 36357 | FS17: 34743 | FT17: 33225 | FU17: 31786 | FV17: 30373 | FW17: 28764 | FX17: 27110 | FY17: 25341 | FZ17: 23702 | GA17: 22022 | GB17: 20467 | GC17: 19094 | GD17: 18110 | GE17: 17126 | GF17: 15990 | GG17: 14733 | GH17: 13394 | GI17: 12104 | GJ17: 10889 | GK17: 9673 | GL17: 8434 | GM17: 7270 | GN17: 6263 | GO17: 5334 | GP17: 4500 | GQ17: 3728 | GR17: 3043 | GS17: 2389 | GT17: 1843 | GU17: 1419 | GV17: 1093 | GW17: 847 | GX17: 660 | GY17: 506 | GZ17: 931 | HA17: 220860 | HB17: 221489 | HC17: 223614 | HD17: 227104 | HE17: 230424 | HF17: 234395 | HG17: 237118 | HH17: 239733 | HI17: 241813 | HJ17: 244341 | HK17: 247114 | HL17: 250042 | HM17: 252961 | HN17: 255218 | HO17: 253370 | HP17: 249393 | HQ17: 245432 | HR17: 240744 | HS17: 235335 | HT17: 228717 | HU17: 219620 | HV17: 210310 | HW17: 201544 | HX17: 193064 | HY17: 187605 | HZ17: 183779 | IA17: 179875 | IB17: 175111 | IC17: 170303 | ID17: 166043 | IE17: 162296 | IF17: 158801 | IG17: 155752 | IH17: 153779 | II17: 152293 | IJ17: 151178 | IK17: 151079 | IL17: 150945 | IM17: 150171 | IN17: 149239 | IO17: 147463 | IP17: 144288 | IQ17: 140675 | IR17: 137167 | IS17: 133364 | IT17: 130449 | IU17: 128707 | IV17: 127325 | IW17: 126091 | IX17: 125186 | IY17: 124213 | IZ17: 122631 | JA17: 120789 | JB17: 118820 | JC17: 116584 | JD17: 114399 | JE17: 112103 | JF17: 109333 | JG17: 106011 | JH17: 102479 | JI17: 98591 | JJ17: 94816 | JK17: 91307 | JL17: 87967 | JM17: 84628 | JN17: 81412 | JO17: 78185 | JP17: 74908 | JQ17: 71654 | JR17: 68413 | JS17: 65055 | JT17: 61644 | JU17: 58096 | JV17: 54232 | JW17: 50358 | JX17: 46670 | JY17: 43253 | JZ17: 40418 | KA17: 38028 | KB17: 35615 | KC17: 32956 | KD17: 30193 | KE17: 27232 | KF17: 24163 | KG17: 21264 | KH17: 18655 | KI17: 16206 | KJ17: 14000 | KK17: 11930 | KL17: 10064 | KM17: 8389 | KN17: 6930 | KO17: 5608 | KP17: 4372 | KQ17: 3379 | KR17: 2571 | KS17: 1963 | KT17: 1496 | KU17: 1147 | KV17: 869 | KW17: 1710
A18: Total Nacional | B18: 2020 | C18: Total | D18: 50390790 | E18: 24679740 | F18: 25711050 | G18: 385600 | H18: 388121 | I18: 394740 | J18: 398807 | K18: 403410 | L18: 408157 | M18: 412107 | N18: 416315 | O18: 420666 | P18: 425820 | Q18: 431052 | R18: 436279 | S18: 441600 | T18: 447356 | U18: 447940 | V18: 447937 | W18: 446762 | X18: 445804 | Y18: 445487 | Z18: 446912 | AA18: 442886 | AB18: 439218 | AC18: 436031 | AD18: 434157 | AE18: 433119 | AF18: 431879 | AG18: 427364 | AH18: 418453 | AI18: 407931 | AJ18: 397360 | AK18: 386635 | AL18: 376292 | AM18: 364919 | AN18: 357138 | AO18: 350210 | AP18: 345181 | AQ18: 341919 | AR18: 338315 | AS18: 333461 | AT18: 328906 | AU18: 321673 | AV18: 312767 | AW18: 301480 | AX18: 292226 | AY18: 281364 | AZ18: 274777 | BA18: 271066 | BB18: 268640 | BC18: 266902 | BD18: 266233 | BE18: 265233 | BF18: 263926 | BG18: 260291 | BH18: 258083 | BI18: 253580 | BJ18: 249490 | BK18: 244021 | BL18: 237236 | BM18: 228802 | BN18: 219180 | BO18: 208563 | BP18: 199187 | BQ18: 189780 | BR18: 181486 | BS18: 172537 | BT18: 164972 | BU18: 156935 | BV18: 148893 | BW18: 140923 | BX18: 133178 | BY18: 125196 | BZ18: 117655 | CA18: 109965 | CB18: 102034 | CC18: 93806 | CD18: 86484 | CE18: 79854 | CF18: 74388 | CG18: 69417 | CH18: 64480 | CI18: 59342 | CJ18: 54172 | CK18: 48767 | CL18: 43063 | CM18: 37713 | CN18: 33192 | CO18: 29092 | CP18: 25382 | CQ18: 21692 | CR18: 18399 | CS18: 15338 | CT18: 12729 | CU18: 10272 | CV18: 8034 | CW18: 6210 | CX18: 4698 | CY18: 3544 | CZ18: 2656 | DA18: 1962 | DB18: 1452 | DC18: 3082 | DD18: 366775 | DE18: 369027 | DF18: 374550 | DG18: 380373 | DH18: 384285 | DI18: 388297 | DJ18: 392854 | DK18: 397419 | DL18: 402082 | DM18: 406201 | DN18: 410601 | DO18: 415467 | DP18: 420903 | DQ18: 426638 | DR18: 426979 | DS18: 426976 | DT18: 427522 | DU18: 428860 | DV18: 430976 | DW18: 433894 | DX18: 435972 | DY18: 437281 | DZ18: 438068 | EA18: 434824 | EB18: 432908 | EC18: 431515 | ED18: 427785 | EE18: 421105 | EF18: 412136 | EG18: 402297 | EH18: 392904 | EI18: 383185 | EJ18: 376009 | EK18: 369972 | EL18: 365689 | EM18: 361492 | EN18: 360404 | EO18: 359418 | EP18: 356514 | EQ18: 351994 | ER18: 346019 | ES18: 335676 | ET18: 326723 | EU18: 316187 | EV18: 307461 | EW18: 300191 | EX18: 296447 | EY18: 293908 | EZ18: 292455 | FA18: 292599 | FB18: 293064 | FC18: 290560 | FD18: 289571 | FE18: 286709 | FF18: 284519 | FG18: 280295 | FH18: 275720 | FI18: 269111 | FJ18: 260434 | FK18: 251371 | FL18: 241837 | FM18: 231770 | FN18: 223281 | FO18: 214104 | FP18: 205413 | FQ18: 195693 | FR18: 186336 | FS18: 176613 | FT18: 167365 | FU18: 158729 | FV18: 150274 | FW18: 141389 | FX18: 132702 | FY18: 123532 | FZ18: 114952 | GA18: 106545 | GB18: 98945 | GC18: 92376 | GD18: 87145 | GE18: 82259 | GF18: 76964 | GG18: 71246 | GH18: 65338 | GI18: 59431 | GJ18: 53652 | GK18: 47999 | GL18: 42382 | GM18: 37147 | GN18: 32496 | GO18: 28060 | GP18: 23980 | GQ18: 20142 | GR18: 16642 | GS18: 13251 | GT18: 10289 | GU18: 7936 | GV18: 6063 | GW18: 4662 | GX18: 3548 | GY18: 2662 | GZ18: 4729 | HA18: 752375 | HB18: 757148 | HC18: 769290 | HD18: 779180 | HE18: 787695 | HF18: 796454 | HG18: 804961 | HH18: 813734 | HI18: 822748 | HJ18: 832021 | HK18: 841653 | HL18: 851746 | HM18: 862503 | HN18: 873994 | HO18: 874919 | HP18: 874913 | HQ18: 874284 | HR18: 874664 | HS18: 876463 | HT18: 880806 | HU18: 878858 | HV18: 876499 | HW18: 874099 | HX18: 868981 | HY18: 866027 | HZ18: 863394 | IA18: 855149 | IB18: 839558 | IC18: 820067 | ID18: 799657 | IE18: 779539 | IF18: 759477 | IG18: 740928 | IH18: 727110 | II18: 715899 | IJ18: 706673 | IK18: 702323 | IL18: 697733 | IM18: 689975 | IN18: 680900 | IO18: 667692 | IP18: 648443 | IQ18: 628203 | IR18: 608413 | IS18: 588825 | IT18: 574968 | IU18: 567513 | IV18: 562548 | IW18: 559357 | IX18: 558832 | IY18: 558297 | IZ18: 554486 | JA18: 549862 | JB18: 544792 | JC18: 538099 | JD18: 529785 | JE18: 519741 | JF18: 506347 | JG18: 489236 | JH18: 470551 | JI18: 450400 | JJ18: 430957 | JK18: 413061 | JL18: 395590 | JM18: 377950 | JN18: 360665 | JO18: 343271 | JP18: 325506 | JQ18: 308288 | JR18: 291907 | JS18: 275470 | JT18: 259044 | JU18: 242667 | JV18: 225566 | JW18: 208758 | JX18: 193029 | JY18: 178799 | JZ18: 166764 | KA18: 156562 | KB18: 146739 | KC18: 136306 | KD18: 125418 | KE18: 114105 | KF18: 102494 | KG18: 91365 | KH18: 81191 | KI18: 71474 | KJ18: 62529 | KK18: 54188 | KL18: 46459 | KM18: 39318 | KN18: 32871 | KO18: 26914 | KP18: 21285 | KQ18: 16499 | KR18: 12634 | KS18: 9607 | KT18: 7318 | KU18: 5510 | KV18: 4114 | KW18: 7811
A19: Total Nacional | B19: 2021 | C19: Cabecera | D19: 38710371 | E19: 18578115 | F19: 20132256 | G19: 269870 | H19: 275471 | I19: 277232 | J19: 282101 | K19: 284504 | L19: 286843 | M19: 289878 | N19: 292476 | O19: 295534 | P19: 298446 | Q19: 301810 | R19: 305124 | S19: 308518 | T19: 312471 | U19: 317071 | V19: 319209 | W19: 320685 | X19: 321821 | Y19: 323769 | Z19: 326714 | AA19: 331703 | AB19: 332837 | AC19: 334528 | AD19: 336443 | AE19: 338909 | AF19: 340570 | AG19: 341164 | AH19: 338615 | AI19: 332134 | AJ19: 323894 | AK19: 315258 | AL19: 306267 | AM19: 297444 | AN19: 287745 | AO19: 280706 | AP19: 274428 | AQ19: 269526 | AR19: 265964 | AS19: 262122 | AT19: 257301 | AU19: 252767 | AV19: 245998 | AW19: 238051 | AX19: 228517 | AY19: 220659 | AZ19: 211847 | BA19: 206404 | BB19: 203337 | BC19: 201413 | BD19: 200126 | BE19: 199721 | BF19: 199016 | BG19: 198089 | BH19: 195400 | BI19: 193842 | BJ19: 190476 | BK19: 187223 | BL19: 182773 | BM19: 177194 | BN19: 170319 | BO19: 162479 | BP19: 153969 | BQ19: 146377 | BR19: 138807 | BS19: 132043 | BT19: 124849 | BU19: 118768 | BV19: 112319 | BW19: 105869 | BX19: 99541 | BY19: 93511 | BZ19: 87397 | CA19: 81594 | CB19: 75776 | CC19: 69910 | CD19: 63940 | CE19: 58620 | CF19: 53845 | CG19: 49805 | CH19: 46185 | CI19: 42648 | CJ19: 39015 | CK19: 35373 | CL19: 31655 | CM19: 27843 | CN19: 24315 | CO19: 21301 | CP19: 18545 | CQ19: 16024 | CR19: 13578 | CS19: 11409 | CT19: 9403 | CU19: 7697 | CV19: 6114 | CW19: 4715 | CX19: 3580 | CY19: 2661 | CZ19: 1968 | DA19: 1444 | DB19: 1043 | DC19: 1903 | DD19: 257417 | DE19: 262594 | DF19: 264176 | DG19: 268453 | DH19: 271853 | DI19: 273898 | DJ19: 276609 | DK19: 279875 | DL19: 283461 | DM19: 286991 | DN19: 290098 | DO19: 293484 | DP19: 297312 | DQ19: 301945 | DR19: 307161 | DS19: 309723 | DT19: 312099 | DU19: 315399 | DV19: 319815 | DW19: 325271 | DX19: 332060 | DY19: 338505 | DZ19: 343845 | EA19: 348058 | EB19: 348407 | EC19: 348557 | ED19: 348324 | EE19: 345669 | EF19: 340427 | EG19: 333161 | EH19: 324974 | EI19: 317070 | EJ19: 308844 | EK19: 302564 | EL19: 297253 | EM19: 293331 | EN19: 289673 | EO19: 288539 | EP19: 287473 | EQ19: 284922 | ER19: 281038 | ES19: 276141 | ET19: 267773 | EU19: 260512 | EV19: 252023 | EW19: 245031 | EX19: 239463 | EY19: 236693 | EZ19: 234921 | FA19: 234064 | FB19: 234528 | FC19: 235319 | FD19: 233708 | FE19: 233294 | FF19: 231343 | FG19: 229790 | FH19: 226476 | FI19: 222768 | FJ19: 217331 | FK19: 210111 | FL19: 202548 | FM19: 194544 | FN19: 186167 | FO19: 179037 | FP19: 171351 | FQ19: 164021 | FR19: 155794 | FS19: 147859 | FT19: 139637 | FU19: 131768 | FV19: 124427 | FW19: 117261 | FX19: 109896 | FY19: 102767 | FZ19: 95294 | GA19: 88270 | GB19: 81451 | GC19: 75305 | GD19: 69992 | GE19: 65600 | GF19: 61528 | GG19: 57210 | GH19: 52643 | GI19: 47982 | GJ19: 43332 | GK19: 38839 | GL19: 34458 | GM19: 30182 | GN19: 26245 | GO19: 22728 | GP19: 19389 | GQ19: 16360 | GR19: 13555 | GS19: 11035 | GT19: 8642 | GU19: 6589 | GV19: 4978 | GW19: 3716 | GX19: 2786 | GY19: 2062 | GZ19: 3391 | HA19: 527287 | HB19: 538065 | HC19: 541408 | HD19: 550554 | HE19: 556357 | HF19: 560741 | HG19: 566487 | HH19: 572351 | HI19: 578995 | HJ19: 585437 | HK19: 591908 | HL19: 598608 | HM19: 605830 | HN19: 614416 | HO19: 624232 | HP19: 628932 | HQ19: 632784 | HR19: 637220 | HS19: 643584 | HT19: 651985 | HU19: 663763 | HV19: 671342 | HW19: 678373 | HX19: 684501 | HY19: 687316 | HZ19: 689127 | IA19: 689488 | IB19: 684284 | IC19: 672561 | ID19: 657055 | IE19: 640232 | IF19: 623337 | IG19: 606288 | IH19: 590309 | II19: 577959 | IJ19: 567759 | IK19: 559199 | IL19: 554503 | IM19: 549595 | IN19: 542223 | IO19: 533805 | IP19: 522139 | IQ19: 505824 | IR19: 489029 | IS19: 472682 | IT19: 456878 | IU19: 445867 | IV19: 440030 | IW19: 436334 | IX19: 434190 | IY19: 434249 | IZ19: 434335 | JA19: 431797 | JB19: 428694 | JC19: 425185 | JD19: 420266 | JE19: 413699 | JF19: 405541 | JG19: 394525 | JH19: 380430 | JI19: 365027 | JJ19: 348513 | JK19: 332544 | JL19: 317844 | JM19: 303394 | JN19: 288870 | JO19: 274562 | JP19: 260178 | JQ19: 245506 | JR19: 231309 | JS19: 217938 | JT19: 204658 | JU19: 191490 | JV19: 178543 | JW19: 165204 | JX19: 152210 | JY19: 140071 | JZ19: 129150 | KA19: 119797 | KB19: 111785 | KC19: 104176 | KD19: 96225 | KE19: 88016 | KF19: 79637 | KG19: 71175 | KH19: 63154 | KI19: 55759 | KJ19: 48727 | KK19: 42269 | KL19: 36306 | KM19: 30798 | KN19: 25763 | KO19: 21252 | KP19: 17149 | KQ19: 13357 | KR19: 10169 | KS19: 7639 | KT19: 5684 | KU19: 4230 | KV19: 3105 | KW19: 5294
A20: Total Nacional | B20: 2021 | C20: Centros Poblados y Rural Disperso | D20: 12405266 | E20: 6459148 | F20: 5946118 | G20: 112807 | H20: 114187 | I20: 114866 | J20: 116426 | K20: 117878 | L20: 119939 | M20: 121445 | N20: 122610 | O20: 123580 | P20: 124836 | Q20: 126464 | R20: 128227 | S20: 129904 | T20: 131140 | U20: 132194 | V20: 130630 | W20: 129275 | X20: 127252 | Y20: 124759 | Z20: 121998 | AA20: 118896 | AB20: 114168 | AC20: 109133 | AD20: 104221 | AE20: 99955 | AF20: 97211 | AG20: 95245 | AH20: 93101 | AI20: 90461 | AJ20: 87949 | AK20: 85775 | AL20: 83796 | AM20: 82026 | AN20: 80112 | AO20: 79119 | AP20: 78232 | AQ20: 77874 | AR20: 77937 | AS20: 77948 | AT20: 77700 | AU20: 77477 | AV20: 76817 | AW20: 75676 | AX20: 73759 | AY20: 72197 | AZ20: 69995 | BA20: 68690 | BB20: 67865 | BC20: 67188 | BD20: 66550 | BE20: 66083 | BF20: 65594 | BG20: 65007 | BH20: 63867 | BI20: 63001 | BJ20: 61663 | BK20: 60610 | BL20: 59393 | BM20: 57975 | BN20: 56232 | BO20: 54283 | BP20: 52013 | BQ20: 50065 | BR20: 48066 | BS20: 46352 | BT20: 44440 | BU20: 42759 | BV20: 40997 | BW20: 39238 | BX20: 37432 | BY20: 35561 | BZ20: 33557 | CA20: 31677 | CB20: 29701 | CC20: 27558 | CD20: 25278 | CE20: 23229 | CF20: 21341 | CG20: 19830 | CH20: 18389 | CI20: 16932 | CJ20: 15411 | CK20: 13925 | CL20: 12344 | CM20: 10652 | CN20: 9066 | CO20: 7767 | CP20: 6640 | CQ20: 5678 | CR20: 4729 | CS20: 3894 | CT20: 3158 | CU20: 2560 | CV20: 2022 | CW20: 1542 | CX20: 1164 | CY20: 866 | CZ20: 644 | DA20: 478 | DB20: 351 | DC20: 644 | DD20: 106733 | DE20: 107983 | DF20: 108607 | DG20: 109691 | DH20: 111932 | DI20: 113605 | DJ20: 114739 | DK20: 115857 | DL20: 116665 | DM20: 117642 | DN20: 118505 | DO20: 119382 | DP20: 120283 | DQ20: 120998 | DR20: 121463 | DS20: 119321 | DT20: 117228 | DU20: 114985 | DV20: 112584 | DW20: 109948 | DX20: 106683 | DY20: 102760 | DZ20: 98993 | EA20: 95645 | EB20: 92017 | EC20: 89804 | ED20: 88426 | EE20: 87089 | EF20: 85368 | EG20: 83376 | EH20: 81428 | EI20: 79658 | EJ20: 77887 | EK20: 76722 | EL20: 75738 | EM20: 75128 | EN20: 74356 | EO20: 74172 | EP20: 74032 | EQ20: 73469 | ER20: 72635 | ES20: 71377 | ET20: 69230 | EU20: 67380 | EV20: 65191 | EW20: 63304 | EX20: 61468 | EY20: 60342 | EZ20: 59428 | FA20: 58684 | FB20: 58210 | FC20: 57718 | FD20: 56674 | FE20: 55936 | FF20: 54871 | FG20: 54063 | FH20: 52991 | FI20: 51950 | FJ20: 50621 | FK20: 49012 | FL20: 47358 | FM20: 45674 | FN20: 43840 | FO20: 42305 | FP20: 40655 | FQ20: 39123 | FR20: 37471 | FS20: 35870 | FT20: 34215 | FU20: 32664 | FV20: 31194 | FW20: 29723 | FX20: 28043 | FY20: 26326 | FZ20: 24495 | GA20: 22812 | GB20: 21102 | GC20: 19518 | GD20: 18110 | GE20: 17060 | GF20: 16032 | GG20: 14875 | GH20: 13601 | GI20: 12282 | GJ20: 11003 | GK20: 9810 | GL20: 8623 | GM20: 7438 | GN20: 6332 | GO20: 5400 | GP20: 4551 | GQ20: 3789 | GR20: 3092 | GS20: 2478 | GT20: 1913 | GU20: 1453 | GV20: 1103 | GW20: 840 | GX20: 647 | GY20: 491 | GZ20: 820 | HA20: 219540 | HB20: 222170 | HC20: 223473 | HD20: 226117 | HE20: 229810 | HF20: 233544 | HG20: 236184 | HH20: 238467 | HI20: 240245 | HJ20: 242478 | HK20: 244969 | HL20: 247609 | HM20: 250187 | HN20: 252138 | HO20: 253657 | HP20: 249951 | HQ20: 246503 | HR20: 242237 | HS20: 237343 | HT20: 231946 | HU20: 225579 | HV20: 216928 | HW20: 208126 | HX20: 199866 | HY20: 191972 | HZ20: 187015 | IA20: 183671 | IB20: 180190 | IC20: 175829 | ID20: 171325 | IE20: 167203 | IF20: 163454 | IG20: 159913 | IH20: 156834 | II20: 154857 | IJ20: 153360 | IK20: 152230 | IL20: 152109 | IM20: 151980 | IN20: 151169 | IO20: 150112 | IP20: 148194 | IQ20: 144906 | IR20: 141139 | IS20: 137388 | IT20: 133299 | IU20: 130158 | IV20: 128207 | IW20: 126616 | IX20: 125234 | IY20: 124293 | IZ20: 123312 | JA20: 121681 | JB20: 119803 | JC20: 117872 | JD20: 115726 | JE20: 113601 | JF20: 111343 | JG20: 108596 | JH20: 105244 | JI20: 101641 | JJ20: 97687 | JK20: 93905 | JL20: 90371 | JM20: 87007 | JN20: 83563 | JO20: 80230 | JP20: 76867 | JQ20: 73453 | JR20: 70096 | JS20: 66755 | JT20: 63280 | JU20: 59720 | JV20: 56027 | JW20: 52053 | JX20: 48090 | JY20: 44331 | JZ20: 40859 | KA20: 37940 | KB20: 35449 | KC20: 32964 | KD20: 30286 | KE20: 27526 | KF20: 24626 | KG20: 21655 | KH20: 18876 | KI20: 16390 | KJ20: 14078 | KK20: 12010 | KL20: 10129 | KM20: 8445 | KN20: 6947 | KO20: 5652 | KP20: 4500 | KQ20: 3455 | KR20: 2617 | KS20: 1969 | KT20: 1484 | KU20: 1125 | KV20: 842 | KW20: 1464
